Workbook
Name AccountrEquity: #REF!
Name IV: #REF!
Name ListCP: #REF!
Name MCK: #REF!

Sheet Tìm nhanh CP
A1: Cách sử dụng | F1: - Phân loại nhóm ngành, HĐKD của doanh nghiệp
F2: - Tìm cổ phiếu tăng trưởng trong quý hiện tại | I2: Chú ý: các DN phần LN ghi 0, LN% cùng kì 100%... Là các DN chưa ra báo cáo
F3: - Tìm nhanh 1CP bằng cách gõ tên vào ô bên dưới | I3: Và EPS cùng kì chỉ tính 3 quý thôi.
A4: 28/04/2026 | H4: Doanh thu | I4: ='Doanh thu'!H2 -> Q1.25 | J4: ='Doanh thu'!I2 -> Q2.25 | K4: ='Doanh thu'!J2 -> Q3.25 | L4: ='Doanh thu'!K2 -> Q4.25 | M4: ='Doanh thu'!L2 -> Q1.26
B5: NHẬP MÃ | H5: Giá trị | I5: =VLOOKUP($B$6,'Doanh thu'!$A$3:$L$2000,8,FALSE) -> 37621674553578 | J5: =VLOOKUP($B$6,'Doanh thu'!$A$3:$L$2000,9,FALSE) -> 35910519111209 | K5: =VLOOKUP($B$6,'Doanh thu'!$A$3:$L$2000,10,FALSE) -> 36407416403924 | L5: =VLOOKUP($B$6,'Doanh thu'!$A$3:$L$2000,11,FALSE) -> 46176484549771 | M5: =VLOOKUP($B$6,'Doanh thu'!$A$3:$L$2000,12,FALSE) -> 52900847302653
B6: hpg | H6: YoY% | I6: =VLOOKUP($B$6,'Doanh thu'!$A$3:$Q$2000,U41,FALSE) -> 0.21940996 | J6: =VLOOKUP($B$6,'Doanh thu'!$A$3:$Q$2000,V41,FALSE) -> -0.092148748 | K6: =VLOOKUP($B$6,'Doanh thu'!$A$3:$Q$2000,W41,FALSE) -> 0.072185691 | L6: =VLOOKUP($B$6,'Doanh thu'!$A$3:$Q$2000,X41,FALSE) -> 0.33879876 | M6: =VLOOKUP($B$6,'Doanh thu'!$A$3:$Q$2000,Y41,FALSE) -> 0.40612687
B8: =VLOOKUP($B$6,LNST!$A$2:$B$1671,2,FALSE) -> Hòa Phát | H8: Lợi nhuận gộp | I8: =I4 -> Q1.25 | J8: =J4 -> Q2.25 | K8: =K4 -> Q3.25 | L8: =L4 -> Q4.25 | M8: =M4 -> Q1.26
H9: Giá trị | I9: =VLOOKUP($B$6,LNG!$A$2:$I$1999,L41,FALSE) -> 5424153925132 | J9: =VLOOKUP($B$6,LNG!$A$2:$I$1999,M41,FALSE) -> 6589722485709 | K9: =VLOOKUP($B$6,LNG!$A$2:$I$1999,N41,FALSE) -> 6087261275166 | L9: =VLOOKUP($B$6,LNG!$A$2:$I$1999,O41,FALSE) -> 6396650497175 | M9: =VLOOKUP($B$6,LNG!$A$2:$I$1999,P41,FALSE) -> 8365068607995
B10: Ngành | C10: =VLOOKUP($B$6,'GIÁ CP'!$K$2:$M$2000,3,FALSE) -> Thép và sản phẩm thép | E10: Giá (VND) | F10: =VLOOKUP($B$6,'GIÁ CP'!$A$2:$D$2000,4,FALSE) -> 27000 | H10: Biên | I10: =I9/I5 -> 0.1441763 | J10: =J9/J5 -> 0.18350396 | K10: =K9/K5 -> 0.16719839 | L10: =L9/L5 -> 0.13852615 | M10: =M9/M5 -> 0.15812731
B11: P/E | C11: =F10/C12 -> 9.8203399 | E11: LNST4Q | F11: =SUM(J13:M13)/10^9 -> 21102.893 | G11: tỷ
B12: EPS | C12: =VLOOKUP(B6,'EPS pha loãng'!$A$1:$D$1672,4,FALSE) -> 2749.3957 | E12: Vốn hóa | F12: =F10*F13/10^9 -> 207237.58 | G12: tỷ | H12: LNST | I12: =I4 -> Q1.25 | J12: =J4 -> Q2.25 | K12: =K4 -> Q3.25 | L12: =L4 -> Q4.25 | M12: =M4 -> Q1.26
B13: P/B | C13: =VLOOKUP($B$6,P.B!$A$2:$I$1997,4,FALSE) -> 1.54 | E13: SLCP | F13: =VLOOKUP($B$6,'SLCP lưu hành'!$A$1:$D$1677,4,FALSE) -> 7675465855 | H13: Giá trị | I13: =VLOOKUP($B$6,LNST!$A$3:$L$1613,LNST!H1,FALSE) -> 3344284694388 | J13: =VLOOKUP($B$6,LNST!$A$3:$L$1613,LNST!I1,FALSE) -> 4256487211764 | K13: =VLOOKUP($B$6,LNST!$A$3:$L$1613,LNST!J1,FALSE) -> 3988318474539 | L13: =VLOOKUP($B$6,LNST!$A$3:$L$1613,LNST!K1,FALSE) -> 3864083625532 | M13: =VLOOKUP($B$6,LNST!$A$3:$L$1613,LNST!L1,FALSE) -> 8994003244142
H14: YoY% | I14: =VLOOKUP($B$6,LNST!$A$3:$S$1671,LNST!M1,FALSE) -> 0.16501702 | J14: =VLOOKUP($B$6,LNST!$A$3:$S$1671,LNST!N1,FALSE) -> 0.28235907 | K14: =VLOOKUP($B$6,LNST!$A$3:$S$1671,LNST!O1,FALSE) -> 0.31934796 | L14: =VLOOKUP($B$6,LNST!$A$3:$S$1671,LNST!P1,FALSE) -> 0.37578196 | M14: =VLOOKUP($B$6,LNST!$A$3:$S$1671,LNST!Q1,FALSE) -> 1.6893653
H16: Trend tăng trưởng
H17: 3Q gần nhất | I17: 2025 so với 2024 | J17: Bình quân 4 năm | L17: ► Đăng ký mở tài khoản CK
H18: =VLOOKUP($B$6,LNST!$A$3:$S$1671,18,FALSE) -> 0.83594504 | I18: =VLOOKUP($B$6,'LNST năm'!$A$2:$J$2000,8,FALSE) -> 0.28521042 | J18: =VLOOKUP($B$6,'LNST năm'!$A$2:$J$2000,9,FALSE) -> 0.2211952 | L18: ► Tham gia Room Tư vấn TVI
L19: Liên hệ trợ lý: | M19: Quỳnh Anh 0395.626.368 (zalo/SĐT)
C20: Sản phẩm dành riêng cho khách hàng của đội ngũ TVI!
H23: 12 | I23: 13
I41: 1 | J41: 2 | K41: 3 | L41: 4 | M41: 5 | N41: 6 | O41: 7 | P41: 8 | Q41: 9 | R41: 10 | S41: 11 | T41: 12 | U41: 13 | V41: 14 | W41: 15 | X41: 16 | Y41: 17 | Z41: 18 | AA41: 19

Sheet Doanh thu
A1: 1 | B1: =A1+1 -> 2 | C1: =B1+1 -> 3 | D1: =C1+1 -> 4 | E1: =D1+1 -> 5 | F1: =E1+1 -> 6 | G1: =F1+1 -> 7 | H1: =G1+1 -> 8 | I1: =H1+1 -> 9 | ... Q1: =P1+1 -> 17
A2: Mã CK | B2: Tên | C2: Sàn | D2: Q1.24 | E2: Q2.24 | F2: Q3.24 | G2: Q4.24 | H2: Q1.25 | I2: Q2.25 | J2: Q3.25 | K2: Q4.25 | L2: Q1.26 | M2: Tăng | N2: Tăng trưởng 1 | O2: Tăng trưởng 2 | P2: Tăng trưởng 3 | Q2: Tăng trưởng 4
A3: AAA | B3: An Phát Bioplastics | C3: HOSE | D3: 2963831327623 | E3: 2782480085532 | F3: 3193399535332 | G3: 3842519612561 | H3: 3856408101891 | I3: 2309974267663 | J3: 2369473905606 | K3: 2192291125691 | L3: =VLOOKUP(A3,Sheet2!$A$1:$E$2000,5,FALSE) -> 2224065397921 | M3: =(H3-D3)/ABS(D3) -> 0.3011564 | N3: =(I3-E3)/ABS(E3) -> -0.16981463 | O3: =(J3-F3)/ABS(F3) -> -0.25800894 | P3: =(K3-G3)/ABS(G3) -> -0.42946521 | Q3: =(L3-H3)/ABS(H3) -> -0.42328059
A4: AAM | B4: Thủy sản Mekong | C4: HOSE | D4: 34565421958 | E4: 34000786456 | F4: 49775079174 | G4: 35142056786 | H4: 54375428180 | I4: 64320760366 | J4: 42450172367 | K4: 9309919152 | L4: =VLOOKUP(A4,Sheet2!$A$1:$E$2000,5,FALSE) -> 33444004710 | M4: =(H4-D4)/ABS(D4) -> 0.57311628 | N4: =(I4-E4)/ABS(E4) -> 0.89174331 | O4: =(J4-F4)/ABS(F4) -> -0.14716012 | P4: =(K4-G4)/ABS(G4) -> -0.73507757 | Q4: =(L4-H4)/ABS(H4) -> -0.38494269
A5: AAT | B5: Tập đoàn Tiên Sơn Thanh Hóa | C5: HOSE | D5: 204683899039 | E5: 179718744794 | F5: 65332021050 | G5: 133277166354 | H5: 207268038521 | I5: 179192185423 | J5: 213108789097 | K5: 409112380019 | L5: =VLOOKUP(A5,Sheet2!$A$1:$E$2000,5,FALSE) -> 235047541189 | M5: =(H5-D5)/ABS(D5) -> 0.012625026 | N5: =(I5-E5)/ABS(E5) -> -0.0029299079 | O5: =(J5-F5)/ABS(F5) -> 2.2619347 | P5: =(K5-G5)/ABS(G5) -> 2.0696359 | Q5: =(L5-H5)/ABS(H5) -> 0.13402695
A6: ABR | B6: Đầu tư Nhãn Hiệu Việt | C6: HOSE | D6: 16478251145 | E6: -4044824828 | F6: 6356015314 | G6: 6106913728 | H6: 6365061149 | I6: 6260496681 | J6: 6107587629 | K6: 6918722892 | L6: =VLOOKUP(A6,Sheet2!$A$1:$E$2000,5,FALSE) -> 6335090877 | M6: =(H6-D6)/ABS(D6) -> -0.61372957 | N6: =(I6-E6)/ABS(E6) -> 2.5477794 | O6: =(J6-F6)/ABS(F6) -> -0.039085445 | P6: =(K6-G6)/ABS(G6) -> 0.1329328 | Q6: =(L6-H6)/ABS(H6) -> -0.0047085599
A7: ABS | B7: DV Nông nghiệp Bình Thuận | C7: HOSE | D7: 35974612465 | E7: 172571741971 | F7: 101023376333 | G7: 86571126645 | H7: 65838104122 | I7: 35255635011 | J7: 30017456759 | K7: 38913283093 | L7: =VLOOKUP(A7,Sheet2!$A$1:$E$2000,5,FALSE) -> 42956175499 | M7: =(H7-D7)/ABS(D7) -> 0.83012685 | N7: =(I7-E7)/ABS(E7) -> -0.79570447 | O7: =(J7-F7)/ABS(F7) -> -0.70286623 | P7: =(K7-G7)/ABS(G7) -> -0.55050506 | Q7: =(L7-H7)/ABS(H7) -> -0.34754841
A8: ABT | B8: Thủy sản Bến Tre | C8: HOSE | D8: 121866077150 | E8: 158672545091 | F8: 151758000405 | G8: 151194400776 | H8: 163767610564 | I8: 177492607944 | J8: 192791973602 | K8: 172768790575 | L8: =VLOOKUP(A8,Sheet2!$A$1:$E$2000,5,FALSE) -> 187835693906 | M8: =(H8-D8)/ABS(D8) -> 0.34383263 | N8: =(I8-E8)/ABS(E8) -> 0.11860945 | O8: =(J8-F8)/ABS(F8) -> 0.27039084 | P8: =(K8-G8)/ABS(G8) -> 0.14269305 | Q8: =(L8-H8)/ABS(H8) -> 0.14696486
A9: ACB | B9: ACB | C9: HOSE | L9: =VLOOKUP(A9,Sheet2!$A$1:$E$2000,5,FALSE) -> 0 | M9: =(H9-D9)/ABS(D9) -> #DIV/0! | N9: =(I9-E9)/ABS(E9) -> #DIV/0! | O9: =(J9-F9)/ABS(F9) -> #DIV/0! | P9: =(K9-G9)/ABS(G9) -> #DIV/0! | Q9: =(L9-H9)/ABS(H9) -> #DIV/0!
A10: ACC | B10: Đầu tư và XD Bình Dương ACC | C10: HOSE | D10: 111374088456 | E10: 143915267320 | F10: 178278200430 | G10: 266456354306 | H10: 130281092225 | I10: 197176052456 | J10: 329365260237 | K10: 111721499096 | L10: =VLOOKUP(A10,Sheet2!$A$1:$E$2000,5,FALSE) -> 151639959465 | M10: =(H10-D10)/ABS(D10) -> 0.16976124 | N10: =(I10-E10)/ABS(E10) -> 0.37008433 | O10: =(J10-F10)/ABS(F10) -> 0.84747916 | P10: =(K10-G10)/ABS(G10) -> -0.5807137 | Q10: =(L10-H10)/ABS(H10) -> 0.16394449
A11: ACG | B11: Gỗ An Cường | C11: HOSE | D11: 694977577935 | E11: 1025855544080 | F11: 1043817347876 | G11: 1216213551747 | H11: 802034366779 | I11: 961089934272 | J11: 1177462519376 | K11: 1668116456301 | L11: =VLOOKUP(A11,Sheet2!$A$1:$E$2000,5,FALSE) -> 1109927947175 | M11: =(H11-D11)/ABS(D11) -> 0.15404351 | N11: =(I11-E11)/ABS(E11) -> -0.063133265 | O11: =(J11-F11)/ABS(F11) -> 0.12803502 | P11: =(K11-G11)/ABS(G11) -> 0.37156542 | Q11: =(L11-H11)/ABS(H11) -> 0.38389076
A12: ACL | B12: Thủy sản CL An Giang | C12: HOSE | D12: 316083402526 | E12: 561952923923 | F12: 415244211842 | G12: 455454523780 | H12: 418239076318 | I12: 581438536254 | J12: 542220091436 | K12: 569426349082 | L12: =VLOOKUP(A12,Sheet2!$A$1:$E$2000,5,FALSE) -> 427960489100 | M12: =(H12-D12)/ABS(D12) -> 0.32319215 | N12: =(I12-E12)/ABS(E12) -> 0.034674813 | O12: =(J12-F12)/ABS(F12) -> 0.30578603 | P12: =(K12-G12)/ABS(G12) -> 0.25023755 | Q12: =(L12-H12)/ABS(H12) -> 0.023243674
A13: ADG | B13: Clever Group | C13: HOSE | D13: 84079773542 | E13: 118397334255 | F13: 108353091804 | G13: 153355832775 | H13: 84023894096 | I13: 114324685009 | J13: 117024077114 | K13: 182993617934 | L13: =VLOOKUP(A13,Sheet2!$A$1:$E$2000,5,FALSE) -> 0 | M13: =(H13-D13)/ABS(D13) -> -0.00066460034 | N13: =(I13-E13)/ABS(E13) -> -0.03439815 | O13: =(J13-F13)/ABS(F13) -> 0.080025269 | P13: =(K13-G13)/ABS(G13) -> 0.19326154 | Q13: =(L13-H13)/ABS(H13) -> -1
A14: ADP | B14: Sơn Á Đông | C14: HOSE | D14: 166343628268 | E14: 245427056333 | F14: 214528322649 | G14: 191555691169 | H14: 200827697629 | I14: 175668167694 | J14: 140076412171 | K14: 135188360842 | L14: =VLOOKUP(A14,Sheet2!$A$1:$E$2000,5,FALSE) -> 154364991714 | M14: =(H14-D14)/ABS(D14) -> 0.20730622 | N14: =(I14-E14)/ABS(E14) -> -0.28423471 | O14: =(J14-F14)/ABS(F14) -> -0.34704933 | P14: =(K14-G14)/ABS(G14) -> -0.2942608 | Q14: =(L14-H14)/ABS(H14) -> -0.23135607
A15: ADS | B15: Dệt sợi DAMSAN | C15: HOSE | D15: 389818986236 | E15: 391134872475 | F15: 365744169139 | G15: 481935542946 | H15: 356587407631 | I15: 445523957067 | J15: 430237235488 | K15: 637589253573 | L15: =VLOOKUP(A15,Sheet2!$A$1:$E$2000,5,FALSE) -> 408191712082 | M15: =(H15-D15)/ABS(D15) -> -0.085248743 | N15: =(I15-E15)/ABS(E15) -> 0.13905455 | O15: =(J15-F15)/ABS(F15) -> 0.17633382 | P15: =(K15-G15)/ABS(G15) -> 0.3229762 | Q15: =(L15-H15)/ABS(H15) -> 0.14471713
A16: AFX | B16: XNK Nông sản Thực phẩm An Giang | C16: HOSE | D16: 396970062620 | E16: 609337697349 | F16: 358650589072 | G16: 692072587810 | H16: 307970517569 | I16: 713323995790 | J16: 735278673951 | K16: 1057049145042 | L16: =VLOOKUP(A16,Sheet2!$A$1:$E$2000,5,FALSE) -> 884015930897 | M16: =(H16-D16)/ABS(D16) -> -0.22419712 | N16: =(I16-E16)/ABS(E16) -> 0.17065463 | O16: =(J16-F16)/ABS(F16) -> 1.0501254 | P16: =(K16-G16)/ABS(G16) -> 0.52736745 | Q16: =(L16-H16)/ABS(H16) -> 1.8704564
A17: AGG | B17: Bất động sản An Gia | C17: HOSE | D17: 1312787417097 | E17: 169043316241 | F17: 268367573759 | G17: 163200171412 | H17: 191772044951 | I17: 193906331896 | J17: 170367839185 | K17: 273042314718 | L17: =VLOOKUP(A17,Sheet2!$A$1:$E$2000,5,FALSE) -> 67263896896 | M17: =(H17-D17)/ABS(D17) -> -0.85391996 | N17: =(I17-E17)/ABS(E17) -> 0.14708074 | O17: =(J17-F17)/ABS(F17) -> -0.3651698 | P17: =(K17-G17)/ABS(G17) -> 0.67305164 | Q17: =(L17-H17)/ABS(H17) -> -0.64925077
A18: AGR | B18: Agriseco | C18: HOSE | D18: 92248189883 | E18: 122101376845 | F18: 98115370595 | G18: 100431955672 | H18: 103757872066 | I18: 97968845732 | J18: 156899568846 | K18: 123385164667 | L18: =VLOOKUP(A18,Sheet2!$A$1:$E$2000,5,FALSE) -> 145316560382 | M18: =(H18-D18)/ABS(D18) -> 0.12476865 | N18: =(I18-E18)/ABS(E18) -> -0.1976434 | O18: =(J18-F18)/ABS(F18) -> 0.59913343 | P18: =(K18-G18)/ABS(G18) -> 0.22854488 | Q18: =(L18-H18)/ABS(H18) -> 0.40053528
A19: ANT | B19: Rau quả thực phẩm An Giang | C19: HOSE | D19: 293176003276 | E19: 404725261338 | F19: 415923493910 | G19: 293941042233 | H19: 467122052811 | I19: 519026260564 | J19: 464650862510 | K19: 348998785003 | L19: =VLOOKUP(A19,Sheet2!$A$1:$E$2000,5,FALSE) -> 0 | M19: =(H19-D19)/ABS(D19) -> 0.59331612 | N19: =(I19-E19)/ABS(E19) -> 0.28241627 | O19: =(J19-F19)/ABS(F19) -> 0.11715464 | P19: =(K19-G19)/ABS(G19) -> 0.1873088 | Q19: =(L19-H19)/ABS(H19) -> -1
A20: ANV | B20: Thủy sản Nam Việt | C20: HOSE | D20: 1016008704124 | E20: 1193412864585 | F20: 1341021310612 | G20: 1360823093592 | H20: 1106263191785 | I20: 1726231655961 | J20: 2000082975336 | K20: 2118930435283 | L20: =VLOOKUP(A20,Sheet2!$A$1:$E$2000,5,FALSE) -> 1841296117934 | M20: =(H20-D20)/ABS(D20) -> 0.088832396 | N20: =(I20-E20)/ABS(E20) -> 0.44646644 | O20: =(J20-F20)/ABS(F20) -> 0.49146248 | P20: =(K20-G20)/ABS(G20) -> 0.55709471 | Q20: =(L20-H20)/ABS(H20) -> 0.66442862
A21: APG | B21: Chứng khoán APG | C21: HOSE | D21: 30204152396 | E21: 65033318681 | F21: 26227531639 | G21: -5443203936 | H21: 24772441725 | I21: 161287771412 | J21: 87245906320 | K21: 73528174391 | L21: =VLOOKUP(A21,Sheet2!$A$1:$E$2000,5,FALSE) -> 84974653113 | M21: =(H21-D21)/ABS(D21) -> -0.17983324 | N21: =(I21-E21)/ABS(E21) -> 1.4800791 | O21: =(J21-F21)/ABS(F21) -> 2.3265009 | P21: =(K21-G21)/ABS(G21) -> 14.508253 | Q21: =(L21-H21)/ABS(H21) -> 2.430209
... A26: AST | B26: Dịch vụ Hàng không Taseco | C26: HOSE | D26: 339525473495 | E26: 309802933086 | F26: 329211695662 | G26: 351502149109 | H26: 384845799703 | I26: 393791048196 | J26: 458209035755 | K26: 490102667620 | L26: =VLOOKUP(A26,Sheet2!$A$1:$E$2000,5,FALSE) -> 555973947060 | M26: =(H26-D26)/ABS(D26) -> 0.13348137 | N26: =(I26-E26)/ABS(E26) -> 0.27110174 | O26: =(J26-F26)/ABS(F26) -> 0.39183705 | P26: =(K26-G26)/ABS(G26) -> 0.39430916 | Q26: =(L26-H26)/ABS(H26) -> 0.44466679
A27: ATP | B27: T.Mại và DV An Thành | C27: HOSE | L27: =VLOOKUP(A27,Sheet2!$A$1:$E$2000,5,FALSE) -> 0 | M27: =(H27-D27)/ABS(D27) -> #DIV/0! | N27: =(I27-E27)/ABS(E27) -> #DIV/0! | O27: =(J27-F27)/ABS(F27) -> #DIV/0! | P27: =(K27-G27)/ABS(G27) -> #DIV/0! | Q27: =(L27-H27)/ABS(H27) -> #DIV/0!
A28: BAF | B28: Nông nghiệp BAF Việt Nam | C28: HOSE | D28: 1292013483890 | E28: 1321178494029 | F28: 1313762843295 | G28: 1713730913054 | H28: 1123604043904 | I28: 1386838129431 | J28: 1136263347895 | K28: 1391145758074 | L28: =VLOOKUP(A28,Sheet2!$A$1:$E$2000,5,FALSE) -> 1762207980539 | M28: =(H28-D28)/ABS(D28) -> -0.1303465 | N28: =(I28-E28)/ABS(E28) -> 0.049697778 | O28: =(J28-F28)/ABS(F28) -> -0.13510771 | P28: =(K28-G28)/ABS(G28) -> -0.18823559 | Q28: =(L28-H28)/ABS(H28) -> 0.56835318
A29: BCE | B29: XD và GT Bình Dương | C29: HOSE | D29: 10588494898 | E29: 16562950556 | F29: 10350287177 | G29: 254464002316 | H29: 9379556294 | I29: 117973529093 | J29: 189949118469 | K29: 562243170086 | L29: =VLOOKUP(A29,Sheet2!$A$1:$E$2000,5,FALSE) -> 63015458144 | M29: =(H29-D29)/ABS(D29) -> -0.11417474 | N29: =(I29-E29)/ABS(E29) -> 6.1227363 | O29: =(J29-F29)/ABS(F29) -> 17.352063 | P29: =(K29-G29)/ABS(G29) -> 1.2095195 | Q29: =(L29-H29)/ABS(H29) -> 5.7183837
A30: BCG | B30: Bamboo Capital | C30: HOSE | D30: 985437239704 | E30: 1114820056534 | F30: 1137868443276 | G30: 1133731815353 | L30: =VLOOKUP(A30,Sheet2!$A$1:$E$2000,5,FALSE) -> 0 | M30: =(H30-D30)/ABS(D30) -> -1 | N30: =(I30-E30)/ABS(E30) -> -1 | O30: =(J30-F30)/ABS(F30) -> -1 | P30: =(K30-G30)/ABS(G30) -> -1 | Q30: =(L30-H30)/ABS(H30) -> #DIV/0!
A31: BCM | B31: Becamex Group | C31: HOSE | D31: 811605444546 | E31: 1156018236714 | F31: 1227612256297 | G31: 2044000623070 | H31: 1842515299282 | I31: 2903596879027 | J31: 828384301042 | K31: 1376454513805 | L31: =VLOOKUP(A31,Sheet2!$A$1:$E$2000,5,FALSE) -> 1104960466553 | M31: =(H31-D31)/ABS(D31) -> 1.2702106 | N31: =(I31-E31)/ABS(E31) -> 1.5117224 | O31: =(J31-F31)/ABS(F31) -> -0.32520688 | P31: =(K31-G31)/ABS(G31) -> -0.32658802 | Q31: =(L31-H31)/ABS(H31) -> -0.40029781
A32: BFC | B32: Phân bón Bình Điền | C32: HOSE | D32: 1940449006153 | E32: 2916008103459 | F32: 2030983062685 | G32: 2470803574580 | H32: 2554263681231 | I32: 3534561210826 | J32: 2059537036302 | K32: 2468094589244 | L32: =VLOOKUP(A32,Sheet2!$A$1:$E$2000,5,FALSE) -> 3345445434562 | M32: =(H32-D32)/ABS(D32) -> 0.3163261 | N32: =(I32-E32)/ABS(E32) -> 0.21212325 | O32: =(J32-F32)/ABS(F32) -> 0.014059188 | P32: =(K32-G32)/ABS(G32) -> -0.0010963985 | Q32: =(L32-H32)/ABS(H32) -> 0.30974944
A33: BHN | B33: HABECO | C33: HOSE | D33: 1308100051331 | E33: 2305566275712 | F33: 2335256892188 | G33: 2270697593043 | H33: 1458025664821 | I33: 2356020079914 | J33: 2507409811105 | K33: 2203147758159 | L33: =VLOOKUP(A33,Sheet2!$A$1:$E$2000,5,FALSE) -> 1929641088961 | M33: =(H33-D33)/ABS(D33) -> 0.11461326 | N33: =(I33-E33)/ABS(E33) -> 0.021883476 | O33: =(J33-F33)/ABS(F33) -> 0.07371905 | P33: =(K33-G33)/ABS(G33) -> -0.029748495 | Q33: =(L33-H33)/ABS(H33) -> 0.32346168
A34: BIC | B34: Bảo hiểm BIDV | C34: HOSE | D34: 984231382085 | E34: 1124794719925 | F34: 983764299627 | G34: 1170862079783 | H34: 1033198742002 | I34: 1120979677832 | J34: 1035612243283 | K34: 1096571314717 | L34: =VLOOKUP(A34,Sheet2!$A$1:$E$2000,5,FALSE) -> 1137200217440 | M34: =(H34-D34)/ABS(D34) -> 0.049751878 | N34: =(I34-E34)/ABS(E34) -> -0.0033917674 | O34: =(J34-F34)/ABS(F34) -> 0.052703624 | P34: =(K34-G34)/ABS(G34) -> -0.063449629 | Q34: =(L34-H34)/ABS(H34) -> 0.1006597
A35: BID | B35: BIDV | C35: HOSE | L35: =VLOOKUP(A35,Sheet2!$A$1:$E$2000,5,FALSE) -> 0 | M35: =(H35-D35)/ABS(D35) -> #DIV/0! | N35: =(I35-E35)/ABS(E35) -> #DIV/0! | O35: =(J35-F35)/ABS(F35) -> #DIV/0! | P35: =(K35-G35)/ABS(G35) -> #DIV/0! | Q35: =(L35-H35)/ABS(H35) -> #DIV/0!
A36: BKG | B36: Đầu tư BKG Việt Nam | C36: HOSE | D36: 69734595158 | E36: 88471245041 | F36: 65169105897 | G36: 65351706715 | H36: 44475337897 | I36: 86302338481 | J36: 41179706272 | K36: 61864883210 | L36: =VLOOKUP(A36,Sheet2!$A$1:$E$2000,5,FALSE) -> 46725536629 | M36: =(H36-D36)/ABS(D36) -> -0.36221989 | N36: =(I36-E36)/ABS(E36) -> -0.024515384 | O36: =(J36-F36)/ABS(F36) -> -0.36811 | P36: =(K36-G36)/ABS(G36) -> -0.053354743 | Q36: =(L36-H36)/ABS(H36) -> 0.050594303
A37: BMC | B37: Khoáng sản Bình Định | C37: HOSE | D37: 40752593359 | E37: 47604246642 | F37: 46710990271 | G37: 60251731910 | H37: 11630507216 | I37: 38966853575 | J37: 39602162013 | K37: 29703235504 | L37: =VLOOKUP(A37,Sheet2!$A$1:$E$2000,5,FALSE) -> 23608555252 | M37: =(H37-D37)/ABS(D37) -> -0.71460694 | N37: =(I37-E37)/ABS(E37) -> -0.18144165 | O37: =(J37-F37)/ABS(F37) -> -0.15218749 | P37: =(K37-G37)/ABS(G37) -> -0.50701441 | Q37: =(L37-H37)/ABS(H37) -> 1.0298818
A38: BMI | B38: Bảo hiểm Bảo Minh | C38: HOSE | D38: 1274319102954 | E38: 1278362337536 | F38: 1284431816427 | G38: 1285634849338 | H38: 1340438820817 | I38: 1349781084472 | J38: 1330844174779 | K38: 1340101826964 | L38: =VLOOKUP(A38,Sheet2!$A$1:$E$2000,5,FALSE) -> 1360420068969 | M38: =(H38-D38)/ABS(D38) -> 0.051886311 | N38: =(I38-E38)/ABS(E38) -> 0.055867374 | O38: =(J38-F38)/ABS(F38) -> 0.036134544 | P38: =(K38-G38)/ABS(G38) -> 0.042365822 | Q38: =(L38-H38)/ABS(H38) -> 0.014906498
A39: BMP | B39: Nhựa Bình Minh | C39: HOSE | D39: 1002851021600 | E39: 1153199582323 | F39: 1406831392235 | G39: 1052796659388 | H39: 1383100181955 | I39: 1308129555745 | J39: 1532289910260 | K39: 1286058323278 | L39: =VLOOKUP(A39,Sheet2!$A$1:$E$2000,5,FALSE) -> 1457310965938 | M39: =(H39-D39)/ABS(D39) -> 0.37916814 | N39: =(I39-E39)/ABS(E39) -> 0.13434793 | O39: =(J39-F39)/ABS(F39) -> 0.089178077 | P39: =(K39-G39)/ABS(G39) -> 0.22156383 | Q39: =(L39-H39)/ABS(H39) -> 0.053655393
A40: BRC | B40: Cao su Bến Thành | C40: HOSE | D40: 73547629597 | E40: 103489553943 | F40: 123717111297 | G40: 118299997313 | H40: 97939222338 | I40: 114457491873 | J40: 111239328391 | K40: 113250645892 | L40: =VLOOKUP(A40,Sheet2!$A$1:$E$2000,5,FALSE) -> 95250799894 | M40: =(H40-D40)/ABS(D40) -> 0.33164349 | N40: =(I40-E40)/ABS(E40) -> 0.10598111 | O40: =(J40-F40)/ABS(F40) -> -0.10085737 | P40: =(K40-G40)/ABS(G40) -> -0.0426826 | Q40: =(L40-H40)/ABS(H40) -> -0.027449906
A41: BSI | B41: Chứng khoán BIDV | C41: HOSE | D41: 351747406193 | E41: 424150114113 | F41: 319111392500 | G41: 318505024865 | H41: 337183663045 | I41: 506431146251 | J41: 687921042574 | K41: 565654599730 | L41: =VLOOKUP(A41,Sheet2!$A$1:$E$2000,5,FALSE) -> 697140773775 | M41: =(H41-D41)/ABS(D41) -> -0.041403982 | N41: =(I41-E41)/ABS(E41) -> 0.19399036 | O41: =(J41-F41)/ABS(F41) -> 1.1557395 | P41: =(K41-G41)/ABS(G41) -> 0.77596758 | Q41: =(L41-H41)/ABS(H41) -> 1.0675402
A42: BSR | B42: Lọc Hóa dầu Bình Sơn | C42: HOSE | D42: 30689342319179 | E42: 24423588755537 | F42: 31945856725324 | G42: 35968276079519 | H42: 31894592097760 | I42: 36771954932170 | J42: 35290234805794 | K42: 37625367271578 | L42: =VLOOKUP(A42,Sheet2!$A$1:$E$2000,5,FALSE) -> 45919538260329 | M42: =(H42-D42)/ABS(D42) -> 0.039272584 | N42: =(I42-E42)/ABS(E42) -> 0.5055918 | O42: =(J42-F42)/ABS(F42) -> 0.10468895 | P42: =(K42-G42)/ABS(G42) -> 0.046070909 | Q42: =(L42-H42)/ABS(H42) -> 0.43972803
A43: BTP | B43: Nhiệt điện Bà Rịa | C43: HOSE | D43: 49337909707 | E43: 154550543175 | F43: 74754248596 | G43: 78764061844 | H43: 56942027607 | I43: 66412488368 | J43: 67796700481 | K43: 72127190454 | L43: =VLOOKUP(A43,Sheet2!$A$1:$E$2000,5,FALSE) -> 54780672813 | M43: =(H43-D43)/ABS(D43) -> 0.15412323 | N43: =(I43-E43)/ABS(E43) -> -0.57028628 | O43: =(J43-F43)/ABS(F43) -> -0.093072277 | P43: =(K43-G43)/ABS(G43) -> -0.084262686 | Q43: =(L43-H43)/ABS(H43) -> -0.03795711
A44: BTT | B44: TM - DV Bến Thành | C44: HOSE | D44: 66140765965 | E44: 69915470607 | F44: 59982950252 | G44: 80478532804 | H44: 79222494630 | I44: 60169253989 | J44: 63070500996 | K44: 66243941752 | L44: =VLOOKUP(A44,Sheet2!$A$1:$E$2000,5,FALSE) -> 61327349085 | M44: =(H44-D44)/ABS(D44) -> 0.19778617 | N44: =(I44-E44)/ABS(E44) -> -0.1394 | O44: =(J44-F44)/ABS(F44) -> 0.051473806 | P44: =(K44-G44)/ABS(G44) -> -0.17687439 | Q44: =(L44-H44)/ABS(H44) -> -0.22588465
...

Sheet Sheet2
A1: AAA | B1: An Phát Bioplastics | C1: HOSE | E1: 2224065397921
A2: AAM | B2: Thủy sản Mekong | C2: HOSE | E2: 33444004710
A3: AAT | B3: Tập đoàn Tiên Sơn Thanh Hóa | C3: HOSE | E3: 235047541189
A4: ABR | B4: Đầu tư Nhãn Hiệu Việt | C4: HOSE | E4: 6335090877
A5: ABS | B5: DV Nông nghiệp Bình Thuận | C5: HOSE | E5: 42956175499
A6: ABT | B6: Thủy sản Bến Tre | C6: HOSE | E6: 187835693906
A7: ACB | B7: ACB | C7: HOSE
A8: ACC | B8: Đầu tư và XD Bình Dương ACC | C8: HOSE | E8: 151639959465
A9: ACG | B9: Gỗ An Cường | C9: HOSE | E9: 1109927947175
A10: ACL | B10: Thủy sản CL An Giang | C10: HOSE | E10: 427960489100
A11: ADG | B11: Clever Group | C11: HOSE
A12: ADP | B12: Sơn Á Đông | C12: HOSE | E12: 154364991714
A13: ADS | B13: Dệt sợi DAMSAN | C13: HOSE | E13: 408191712082
A14: AFX | B14: XNK Nông sản Thực phẩm An Giang | C14: HOSE | E14: 884015930897
A15: AGG | B15: Bất động sản An Gia | C15: HOSE | E15: 67263896896
A16: AGR | B16: Agriseco | C16: HOSE | E16: 145316560382
A17: ANT | B17: Rau quả thực phẩm An Giang | C17: HOSE
A18: ANV | B18: Thủy sản Nam Việt | C18: HOSE | E18: 1841296117934
A19: APG | B19: Chứng khoán APG | C19: HOSE | E19: 84974653113
A20: APH | B20: Tập đoàn An Phát Holdings | C20: HOSE | E20: 2224721494680
A21: ASG | B21: Tập đoàn ASG | C21: HOSE | E21: 661404788597
A22: ASM | B22: Tập đoàn Sao Mai | C22: HOSE | E22: 2469598309439
A23: ASP | B23: Dầu khí An Pha | C23: HOSE | E23: 794013619169
A24: AST | B24: Dịch vụ Hàng không Taseco | C24: HOSE | E24: 555973947060
A25: ATP | B25: T.Mại và DV An Thành | C25: HOSE
A26: BAF | B26: Nông nghiệp BAF Việt Nam | C26: HOSE | E26: 1762207980539
A27: BCE | B27: XD và GT Bình Dương | C27: HOSE | E27: 63015458144
A28: BCG | B28: Bamboo Capital | C28: HOSE
A29: BCM | B29: Becamex Group | C29: HOSE | E29: 1104960466553
A30: BFC | B30: Phân bón Bình Điền | C30: HOSE | E30: 3345445434562
A31: BHN | B31: HABECO | C31: HOSE | E31: 1929641088961
A32: BIC | B32: Bảo hiểm BIDV | C32: HOSE | E32: 1137200217440
A33: BID | B33: BIDV | C33: HOSE
A34: BKG | B34: Đầu tư BKG Việt Nam | C34: HOSE | E34: 46725536629
A35: BMC | B35: Khoáng sản Bình Định | C35: HOSE | E35: 23608555252
A36: BMI | B36: Bảo hiểm Bảo Minh | C36: HOSE | E36: 1360420068969
A37: BMP | B37: Nhựa Bình Minh | C37: HOSE | E37: 1457310965938
A38: BRC | B38: Cao su Bến Thành | C38: HOSE | E38: 95250799894
A39: BSI | B39: Chứng khoán BIDV | C39: HOSE | E39: 697140773775
A40: BSR | B40: Lọc Hóa dầu Bình Sơn | C40: HOSE | E40: 45919538260329
...

Sheet LNST
A1: 1 | B1: 2 | C1: 3 | D1: 4 | E1: 5 | F1: 6 | G1: 7 | H1: 8 | I1: 9 | J1: 10 | K1: 11 | L1: 12 | M1: 13 | N1: 14 | O1: 15 | P1: 16 | Q1: 17 | R1: 18 | S1: 19 | T1: 20
A2: Mã CP | B2: Tên | C2: Sàn | D2: ='Doanh thu'!D2 -> Q1.24 | E2: ='Doanh thu'!E2 -> Q2.24 | F2: ='Doanh thu'!F2 -> Q3.24 | G2: ='Doanh thu'!G2 -> Q4.24 | H2: ='Doanh thu'!H2 -> Q1.25 | I2: ='Doanh thu'!I2 -> Q2.25 | J2: ='Doanh thu'!J2 -> Q3.25 | K2: ='Doanh thu'!K2 -> Q4.25 | L2: ='Doanh thu'!L2 -> Q1.26 | M2: Tăng trưởng 5 | N2: Tăng trưởng 1 | O2: Tăng trưởng 2 | P2: Tăng trưởng 3 | Q2: Tăng trưởng 4 | R2: Luỹ kế 3 quý | S2: Lũy kế 4 quý | T2: 2025
A3: AAA | B3: An Phát Bioplastics | C3: HOSE | D3: 134706559842 | E3: 135887872408 | F3: 21799597923 | G3: 76186464918 | H3: 45239813399 | I3: 131689030063 | J3: 117554438469 | K3: 78429315431 | L3: =VLOOKUP(A3,Sheet1!$A$1:$E$2000,5,FALSE) -> 153668061513 | M3: =(H3-D3)/ABS(D3) -> -0.66416028 | N3: =(I3-E3)/ABS(E3) -> -0.030899316 | O3: =(J3-F3)/ABS(F3) -> 4.3925049 | P3: =(K3-G3)/ABS(G3) -> 0.029438963 | Q3: =(L3-H3)/ABS(H3) -> 2.3967439 | R3: =(SUM(J3:L3)-SUM(F3:H3))/ABS(SUM(F3:H3)) -> 1.4412615 | S3: =SUM(I3:L3)/SUM(E3:H3)-1 -> 0.72453291 | T3: =SUM(I3:L3) -> 481340845476
A4: AAM | B4: Thủy sản Mekong | C4: HOSE | D4: -2071987027 | E4: -1615877371 | F4: -1272980613 | G4: -1334838721 | H4: 1208511116 | I4: 1128258987 | J4: 399288553 | K4: -889306322 | L4: =VLOOKUP(A4,Sheet1!$A$1:$E$2000,5,FALSE) -> 2387603772 | M4: =(H4-D4)/ABS(D4) -> 1.5832619 | N4: =(I4-E4)/ABS(E4) -> 1.6982331 | O4: =(J4-F4)/ABS(F4) -> 1.3136643 | P4: =(K4-G4)/ABS(G4) -> 0.33377246 | Q4: =(L4-H4)/ABS(H4) -> 0.97565727 | R4: =(SUM(J4:L4)-SUM(F4:H4))/ABS(SUM(F4:H4)) -> 2.3560887 | S4: =SUM(I4:L4)/SUM(E4:H4)-1 -> -2.0035352 | T4: =SUM(I4:L4) -> 3025844990
A5: AAT | B5: Tập đoàn Tiên Sơn Thanh Hóa | C5: HOSE | D5: 2124587103 | E5: 1384750361 | F5: 2383114722 | G5: -17222060883 | H5: 9554449402 | I5: 5124448103 | J5: 8545005597 | K5: 499336750 | L5: =VLOOKUP(A5,Sheet1!$A$1:$E$2000,5,FALSE) -> 490938501 | M5: =(H5-D5)/ABS(D5) -> 3.4970853 | N5: =(I5-E5)/ABS(E5) -> 2.7006295 | O5: =(J5-F5)/ABS(F5) -> 2.5856459 | P5: =(K5-G5)/ABS(G5) -> 1.028994 | Q5: =(L5-H5)/ABS(H5) -> -0.94861677 | R5: =(SUM(J5:L5)-SUM(F5:H5))/ABS(SUM(F5:H5)) -> 2.8043877 | S5: =SUM(I5:L5)/SUM(E5:H5)-1 -> -4.7591493 | T5: =SUM(I5:L5) -> 14659728951
A6: ABR | B6: Đầu tư Nhãn Hiệu Việt | C6: HOSE | D6: 4769015353 | E6: 5469636513 | F6: 3094015192 | G6: 6405236123 | H6: 3676868740 | I6: 3321543329 | J6: 2497751218 | K6: 5404974481 | L6: =VLOOKUP(A6,Sheet1!$A$1:$E$2000,5,FALSE) -> 2370604829 | M6: =(H6-D6)/ABS(D6) -> -0.22900883 | N6: =(I6-E6)/ABS(E6) -> -0.39273052 | O6: =(J6-F6)/ABS(F6) -> -0.19271527 | P6: =(K6-G6)/ABS(G6) -> -0.15616312 | Q6: =(L6-H6)/ABS(H6) -> -0.35526531 | R6: =(SUM(J6:L6)-SUM(F6:H6))/ABS(SUM(F6:H6)) -> -0.22030685 | S6: =SUM(I6:L6)/SUM(E6:H6)-1 -> -0.27088644 | T6: =SUM(I6:L6) -> 13594873857
A7: ABS | B7: DV Nông nghiệp Bình Thuận | C7: HOSE | D7: 3460566330 | E7: 3388473406 | F7: 259712297 | G7: -4549350892 | H7: -1702820627 | I7: -293175539707 | J7: 1663531866 | K7: -218034521633 | L7: =VLOOKUP(A7,Sheet1!$A$1:$E$2000,5,FALSE) -> -1741076711 | M7: =(H7-D7)/ABS(D7) -> -1.4920641 | N7: =(I7-E7)/ABS(E7) -> -87.521423 | O7: =(J7-F7)/ABS(F7) -> 5.4052873 | P7: =(K7-G7)/ABS(G7) -> -46.926512 | Q7: =(L7-H7)/ABS(H7) -> -0.022466303 | R7: =(SUM(J7:L7)-SUM(F7:H7))/ABS(SUM(F7:H7)) -> -35.397756 | S7: =SUM(I7:L7)/SUM(E7:H7)-1 -> 195.34808 | T7: =SUM(I7:L7) -> -511287606185
A8: ABT | B8: Thủy sản Bến Tre | C8: HOSE | D8: 11171311500 | E8: 33723859148 | F8: 18494999690 | G8: 38098722619 | H8: 22142257722 | I8: 61695732808 | J8: 40250553945 | K8: 33885771947 | L8: =VLOOKUP(A8,Sheet1!$A$1:$E$2000,5,FALSE) -> 22273623047 | M8: =(H8-D8)/ABS(D8) -> 0.9820643 | N8: =(I8-E8)/ABS(E8) -> 0.82943869 | O8: =(J8-F8)/ABS(F8) -> 1.1762938 | P8: =(K8-G8)/ABS(G8) -> -0.11057984 | Q8: =(L8-H8)/ABS(H8) -> 0.0059327882 | R8: =(SUM(J8:L8)-SUM(F8:H8))/ABS(SUM(F8:H8)) -> 0.22447131 | S8: =SUM(I8:L8)/SUM(E8:H8)-1 -> 0.40588572 | T8: =SUM(I8:L8) -> 158105681747
A9: ACB | B9: ACB | C9: HOSE | D9: 3905419000000 | E9: 4468590000000 | F9: 3870395000000 | G9: 4545364000000 | H9: 3678266000000 | I9: 4881159000000 | J9: 4280589000000 | K9: 2784685000000 | L9: =VLOOKUP(A9,Sheet1!$A$1:$E$2000,5,FALSE) -> 4320388000000 | M9: =(H9-D9)/ABS(D9) -> -0.058163541 | N9: =(I9-E9)/ABS(E9) -> 0.092326439 | O9: =(J9-F9)/ABS(F9) -> 0.10598246 | P9: =(K9-G9)/ABS(G9) -> -0.3873571 | Q9: =(L9-H9)/ABS(H9) -> 0.17457193 | R9: =(SUM(J9:L9)-SUM(F9:H9))/ABS(SUM(F9:H9)) -> -0.058571319 | S9: =SUM(I9:L9)/SUM(E9:H9)-1 -> -0.017859136 | T9: =SUM(I9:L9) -> 16266821000000
A10: ACC | B10: Đầu tư và XD Bình Dương ACC | C10: HOSE | D10: 10263379944 | E10: 7509069684 | F10: 19862872999 | G10: 14654868394 | H10: 8923367707 | I10: 8189276245 | J10: 24554035346 | K10: 10389524464 | L10: =VLOOKUP(A10,Sheet1!$A$1:$E$2000,5,FALSE) -> 5708706572 | M10: =(H10-D10)/ABS(D10) -> -0.13056247 | N10: =(I10-E10)/ABS(E10) -> 0.090584665 | O10: =(J10-F10)/ABS(F10) -> 0.23617743 | P10: =(K10-G10)/ABS(G10) -> -0.29105304 | Q10: =(L10-H10)/ABS(H10) -> -0.36025201 | R10: =(SUM(J10:L10)-SUM(F10:H10))/ABS(SUM(F10:H10)) -> -0.064198239 | S10: =SUM(I10:L10)/SUM(E10:H10)-1 -> -0.041386237 | T10: =SUM(I10:L10) -> 48841542627
A11: ACG | B11: Gỗ An Cường | C11: HOSE | D11: 81419524081 | E11: 118128861982 | F11: 130420988660 | G11: 90002611157 | H11: 85008966539 | I11: 137937351417 | J11: 135353838052 | K11: 145688868370 | L11: =VLOOKUP(A11,Sheet1!$A$1:$E$2000,5,FALSE) -> 111902787167 | M11: =(H11-D11)/ABS(D11) -> 0.044085771 | N11: =(I11-E11)/ABS(E11) -> 0.16768543 | O11: =(J11-F11)/ABS(F11) -> 0.037822512 | P11: =(K11-G11)/ABS(G11) -> 0.61871824 | Q11: =(L11-H11)/ABS(H11) -> 0.31636452 | R11: =(SUM(J11:L11)-SUM(F11:H11))/ABS(SUM(F11:H11)) -> 0.28652127 | S11: =SUM(I11:L11)/SUM(E11:H11)-1 -> 0.25337864 | T11: =SUM(I11:L11) -> 530882845006
A12: ACL | B12: Thủy sản CL An Giang | C12: HOSE | D12: 2274571084 | E12: 2780676755 | F12: 3353366474 | G12: 2356628868 | H12: 2590594007 | I12: 6466449988 | J12: 13967390002 | K12: 11311980638 | L12: =VLOOKUP(A12,Sheet1!$A$1:$E$2000,5,FALSE) -> 3439078053 | M12: =(H12-D12)/ABS(D12) -> 0.13893737 | N12: =(I12-E12)/ABS(E12) -> 1.325495 | O12: =(J12-F12)/ABS(F12) -> 3.1651845 | P12: =(K12-G12)/ABS(G12) -> 3.8000688 | Q12: =(L12-H12)/ABS(H12) -> 0.3275249 | R12: =(SUM(J12:L12)-SUM(F12:H12))/ABS(SUM(F12:H12)) -> 2.4598084 | S12: =SUM(I12:L12)/SUM(E12:H12)-1 -> 2.1751695 | T12: =SUM(I12:L12) -> 35184898681
A13: ADG | B13: Clever Group | C13: HOSE | D13: -3285481898 | E13: 10710958142 | F13: -4568301656 | G13: 14936070274 | H13: -4973640619 | I13: 5013562564 | J13: 31660653 | K13: 18720935018 | L13: =VLOOKUP(A13,Sheet1!$A$1:$E$2000,5,FALSE) -> 0 | M13: =(H13-D13)/ABS(D13) -> -0.51382378 | N13: =(I13-E13)/ABS(E13) -> -0.53192212 | O13: =(J13-F13)/ABS(F13) -> 1.0069305 | P13: =(K13-G13)/ABS(G13) -> 0.25340432 | Q13: =(L13-H13)/ABS(H13) -> 1 | R13: =(SUM(J13:L13)-SUM(F13:H13))/ABS(SUM(F13:H13)) -> 2.4764833 | S13: =SUM(I13:L13)/SUM(E13:H13)-1 -> 0.47569271 | T13: =SUM(I13:L13) -> 23766158235
A14: ADP | B14: Sơn Á Đông | C14: HOSE | D14: 22523954117 | E14: 27732271023 | F14: 18423800383 | G14: 16633957477 | H14: 22038189566 | I14: 22597878540 | J14: 12780298221 | K14: 19044171289 | L14: =VLOOKUP(A14,Sheet1!$A$1:$E$2000,5,FALSE) -> 15837757005 | M14: =(H14-D14)/ABS(D14) -> -0.021566575 | N14: =(I14-E14)/ABS(E14) -> -0.18514144 | O14: =(J14-F14)/ABS(F14) -> -0.30631585 | P14: =(K14-G14)/ABS(G14) -> 0.1448972 | Q14: =(L14-H14)/ABS(H14) -> -0.28134945 | R14: =(SUM(J14:L14)-SUM(F14:H14))/ABS(SUM(F14:H14)) -> -0.16522575 | S14: =SUM(I14:L14)/SUM(E14:H14)-1 -> -0.17173664 | T14: =SUM(I14:L14) -> 70260105055
... A26: AST | B26: Dịch vụ Hàng không Taseco | C26: HOSE | D26: 34931983132 | E26: 32631112035 | F26: 38911653043 | G26: 42146310230 | H26: 54663465814 | I26: 62553199290 | J26: 69077871933 | K26: 63875739677 | L26: =VLOOKUP(A26,Sheet1!$A$1:$E$2000,5,FALSE) -> 100919143835 | M26: =(H26-D26)/ABS(D26) -> 0.56485435 | N26: =(I26-E26)/ABS(E26) -> 0.91698031 | O26: =(J26-F26)/ABS(F26) -> 0.77524897 | P26: =(K26-G26)/ABS(G26) -> 0.51557134 | Q26: =(L26-H26)/ABS(H26) -> 0.84619 | R26: =(SUM(J26:L26)-SUM(F26:H26))/ABS(SUM(F26:H26)) -> 0.72318223 | S26: =SUM(I26:L26)/SUM(E26:H26)-1 -> 0.76074535 | T26: =SUM(I26:L26) -> 296425954735
A27: ATP | B27: T.Mại và DV An Thành | C27: HOSE | L27: =VLOOKUP(A27,Sheet1!$A$1:$E$2000,5,FALSE) -> 0 | M27: =(H27-D27)/ABS(D27) -> #DIV/0! | N27: =(I27-E27)/ABS(E27) -> #DIV/0! | O27: =(J27-F27)/ABS(F27) -> #DIV/0! | P27: =(K27-G27)/ABS(G27) -> #DIV/0! | Q27: =(L27-H27)/ABS(H27) -> #DIV/0! | R27: =(SUM(J27:L27)-SUM(F27:H27))/ABS(SUM(F27:H27)) -> #DIV/0! | S27: =SUM(I27:L27)/SUM(E27:H27)-1 -> #DIV/0! | T27: =SUM(I27:L27) -> 0
A28: BAF | B28: Nông nghiệp BAF Việt Nam | C28: HOSE | D28: 119523556707 | E28: 34442878688 | F28: 60366065297 | G28: 102715019494 | H28: 132447048246 | I28: 210069572013 | J28: 20640704588 | K28: -236536147824 | L28: =VLOOKUP(A28,Sheet1!$A$1:$E$2000,5,FALSE) -> 206000611406 | M28: =(H28-D28)/ABS(D28) -> 0.10812506 | N28: =(I28-E28)/ABS(E28) -> 5.0990713 | O28: =(J28-F28)/ABS(F28) -> -0.65807438 | P28: =(K28-G28)/ABS(G28) -> -3.302839 | Q28: =(L28-H28)/ABS(H28) -> 0.55534317 | R28: =(SUM(J28:L28)-SUM(F28:H28))/ABS(SUM(F28:H28)) -> -1.0334819 | S28: =SUM(I28:L28)/SUM(E28:H28)-1 -> -0.39335659 | T28: =SUM(I28:L28) -> 200174740183
A29: BCE | B29: XD và GT Bình Dương | C29: HOSE | D29: -4712977951 | E29: -11814035796 | F29: -9666591352 | G29: 100580947209 | H29: -5099003781 | I29: 5565764350 | J29: 3086545624 | K29: 98186900087 | L29: =VLOOKUP(A29,Sheet1!$A$1:$E$2000,5,FALSE) -> -21356676077 | M29: =(H29-D29)/ABS(D29) -> -0.081906988 | N29: =(I29-E29)/ABS(E29) -> 1.4711146 | O29: =(J29-F29)/ABS(F29) -> 1.3193003 | P29: =(K29-G29)/ABS(G29) -> -0.023802193 | Q29: =(L29-H29)/ABS(H29) -> -3.1884017 | R29: =(SUM(J29:L29)-SUM(F29:H29))/ABS(SUM(F29:H29)) -> -0.068735748 | S29: =SUM(I29:L29)/SUM(E29:H29)-1 -> 0.15514883 | T29: =SUM(I29:L29) -> 85482533984
A30: BCG | B30: Bamboo Capital | C30: HOSE | D30: 13634044335 | E30: 131908086830 | F30: 131526669847 | G30: 126944657704 | L30: =VLOOKUP(A30,Sheet1!$A$1:$E$2000,5,FALSE) -> 0 | M30: =(H30-D30)/ABS(D30) -> -1 | N30: =(I30-E30)/ABS(E30) -> -1 | O30: =(J30-F30)/ABS(F30) -> -1 | P30: =(K30-G30)/ABS(G30) -> -1 | Q30: =(L30-H30)/ABS(H30) -> #DIV/0! | R30: =(SUM(J30:L30)-SUM(F30:H30))/ABS(SUM(F30:H30)) -> -1 | S30: =SUM(I30:L30)/SUM(E30:H30)-1 -> -1 | T30: =SUM(I30:L30) -> 0
A31: BCM | B31: Becamex Group | C31: HOSE | D31: 118116106443 | E31: 273356050769 | F31: 344394978084 | G31: 1451224034015 | H31: 358265688293 | I31: 1475637440340 | J31: 415683449300 | K31: 1238878137592 | L31: =VLOOKUP(A31,Sheet1!$A$1:$E$2000,5,FALSE) -> 279562828161 | M31: =(H31-D31)/ABS(D31) -> 2.0331654 | N31: =(I31-E31)/ABS(E31) -> 4.3982249 | O31: =(J31-F31)/ABS(F31) -> 0.20699626 | P31: =(K31-G31)/ABS(G31) -> -0.14632193 | Q31: =(L31-H31)/ABS(H31) -> -0.21967736 | R31: =(SUM(J31:L31)-SUM(F31:H31))/ABS(SUM(F31:H31)) -> -0.10202974 | S31: =SUM(I31:L31)/SUM(E31:H31)-1 -> 0.40478931 | T31: =SUM(I31:L31) -> 3409761855393
A32: BFC | B32: Phân bón Bình Điền | C32: HOSE | D32: 64816208445 | E32: 167638856983 | F32: 52678365892 | G32: 71872920058 | H32: 92613952907 | I32: 115702421755 | J32: 61172285525 | K32: 40387581258 | L32: =VLOOKUP(A32,Sheet1!$A$1:$E$2000,5,FALSE) -> 124201533146 | M32: =(H32-D32)/ABS(D32) -> 0.42887026 | N32: =(I32-E32)/ABS(E32) -> -0.30981144 | O32: =(J32-F32)/ABS(F32) -> 0.16124114 | P32: =(K32-G32)/ABS(G32) -> -0.43806956 | Q32: =(L32-H32)/ABS(H32) -> 0.34106719 | R32: =(SUM(J32:L32)-SUM(F32:H32))/ABS(SUM(F32:H32)) -> 0.039583504 | S32: =SUM(I32:L32)/SUM(E32:H32)-1 -> -0.11262945 | T32: =SUM(I32:L32) -> 341463821684
A33: BHN | B33: HABECO | C33: HOSE | D33: -5236096891 | E33: 153848022623 | F33: 124086518728 | G33: 109496209431 | H33: 32842643756 | I33: 143011122629 | J33: 221041322040 | K33: 71621671782 | L33: =VLOOKUP(A33,Sheet1!$A$1:$E$2000,5,FALSE) -> 77222524813 | M33: =(H33-D33)/ABS(D33) -> 7.2723522 | N33: =(I33-E33)/ABS(E33) -> -0.070438994 | O33: =(J33-F33)/ABS(F33) -> 0.7813484 | P33: =(K33-G33)/ABS(G33) -> -0.34589816 | Q33: =(L33-H33)/ABS(H33) -> 1.3512883 | R33: =(SUM(J33:L33)-SUM(F33:H33))/ABS(SUM(F33:H33)) -> 0.38832693 | S33: =SUM(I33:L33)/SUM(E33:H33)-1 -> 0.22038808 | T33: =SUM(I33:L33) -> 512896641264
A34: BIC | B34: Bảo hiểm BIDV | C34: HOSE | D34: 104970237416 | E34: 167373086527 | F34: 70924609094 | G34: 151417674464 | H34: 154128694295 | I34: 172341774795 | J34: 91033604240 | K34: 122927777632 | L34: =VLOOKUP(A34,Sheet1!$A$1:$E$2000,5,FALSE) -> 87245176382 | M34: =(H34-D34)/ABS(D34) -> 0.46830852 | N34: =(I34-E34)/ABS(E34) -> 0.029686304 | O34: =(J34-F34)/ABS(F34) -> 0.28352634 | P34: =(K34-G34)/ABS(G34) -> -0.18815437 | Q34: =(L34-H34)/ABS(H34) -> -0.43394592 | R34: =(SUM(J34:L34)-SUM(F34:H34))/ABS(SUM(F34:H34)) -> -0.19992091 | S34: =SUM(I34:L34)/SUM(E34:H34)-1 -> -0.12925715 | T34: =SUM(I34:L34) -> 473548333049
A35: BID | B35: BIDV | C35: HOSE | D35: 5812648000000 | E35: 6365954000000 | F35: 5151318000000 | G35: 7810117000000 | H35: 5840373000000 | I35: 6755001000000 | J35: 5952964000000 | K35: 11355926000000 | L35: =VLOOKUP(A35,Sheet1!$A$1:$E$2000,5,FALSE) -> 6800834000000 | M35: =(H35-D35)/ABS(D35) -> 0.004769771 | N35: =(I35-E35)/ABS(E35) -> 0.0611137 | O35: =(J35-F35)/ABS(F35) -> 0.15561959 | P35: =(K35-G35)/ABS(G35) -> 0.45400203 | Q35: =(L35-H35)/ABS(H35) -> 0.164452 | R35: =(SUM(J35:L35)-SUM(F35:H35))/ABS(SUM(F35:H35)) -> 0.28230881 | S35: =SUM(I35:L35)/SUM(E35:H35)-1 -> 0.22635954 | T35: =SUM(I35:L35) -> 30864725000000
A36: BKG | B36: Đầu tư BKG Việt Nam | C36: HOSE | D36: 4017323438 | E36: 4254574626 | F36: 2708878812 | G36: 3578475140 | H36: 2696445314 | I36: 3422584599 | J36: 1316318299 | K36: 2673409534 | L36: =VLOOKUP(A36,Sheet1!$A$1:$E$2000,5,FALSE) -> 1648718602 | M36: =(H36-D36)/ABS(D36) -> -0.32879556 | N36: =(I36-E36)/ABS(E36) -> -0.19555187 | O36: =(J36-F36)/ABS(F36) -> -0.51407265 | P36: =(K36-G36)/ABS(G36) -> -0.25291935 | Q36: =(L36-H36)/ABS(H36) -> -0.38855849 | R36: =(SUM(J36:L36)-SUM(F36:H36))/ABS(SUM(F36:H36)) -> -0.37237618 | S36: =SUM(I36:L36)/SUM(E36:H36)-1 -> -0.31554803 | T36: =SUM(I36:L36) -> 9061031034
A37: BMC | B37: Khoáng sản Bình Định | C37: HOSE | D37: 4762071361 | E37: 6748284381 | F37: 6119439311 | G37: 7911643781 | H37: 897347845 | I37: 3774810543 | J37: 4262062451 | K37: 2582615142 | L37: =VLOOKUP(A37,Sheet1!$A$1:$E$2000,5,FALSE) -> 1481978528 | M37: =(H37-D37)/ABS(D37) -> -0.81156355 | N37: =(I37-E37)/ABS(E37) -> -0.44062663 | O37: =(J37-F37)/ABS(F37) -> -0.30352076 | P37: =(K37-G37)/ABS(G37) -> -0.67356782 | Q37: =(L37-H37)/ABS(H37) -> 0.65150954 | R37: =(SUM(J37:L37)-SUM(F37:H37))/ABS(SUM(F37:H37)) -> -0.44222831 | S37: =SUM(I37:L37)/SUM(E37:H37)-1 -> -0.44172969 | T37: =SUM(I37:L37) -> 12101466664
A38: BMI | B38: Bảo hiểm Bảo Minh | C38: HOSE | D38: 72723951668 | E38: 70694000582 | F38: 51168094654 | G38: 43087995325 | H38: 63059823482 | I38: 80431469454 | J38: 112712232202 | K38: 3583116939 | L38: =VLOOKUP(A38,Sheet1!$A$1:$E$2000,5,FALSE) -> 55556275286 | M38: =(H38-D38)/ABS(D38) -> -0.13288783 | N38: =(I38-E38)/ABS(E38) -> 0.13774109 | O38: =(J38-F38)/ABS(F38) -> 1.2027835 | P38: =(K38-G38)/ABS(G38) -> -0.91684187 | Q38: =(L38-H38)/ABS(H38) -> -0.11899095 | R38: =(SUM(J38:L38)-SUM(F38:H38))/ABS(SUM(F38:H38)) -> 0.092398224 | S38: =SUM(I38:L38)/SUM(E38:H38)-1 -> 0.10645669 | T38: =SUM(I38:L38) -> 252283093881
A39: BMP | B39: Nhựa Bình Minh | C39: HOSE | D39: 189875059628 | E39: 280300515276 | F39: 289630912189 | G39: 230955242045 | H39: 286910617568 | I39: 329900327324 | J39: 350581005736 | K39: 261343222934 | L39: =VLOOKUP(A39,Sheet1!$A$1:$E$2000,5,FALSE) -> 303956059754 | M39: =(H39-D39)/ABS(D39) -> 0.51104952 | N39: =(I39-E39)/ABS(E39) -> 0.17695227 | O39: =(J39-F39)/ABS(F39) -> 0.21044057 | P39: =(K39-G39)/ABS(G39) -> 0.13157519 | Q39: =(L39-H39)/ABS(H39) -> 0.059410287 | R39: =(SUM(J39:L39)-SUM(F39:H39))/ABS(SUM(F39:H39)) -> 0.13422161 | S39: =SUM(I39:L39)/SUM(E39:H39)-1 -> 0.14523232 | T39: =SUM(I39:L39) -> 1245780615748
A40: BRC | B40: Cao su Bến Thành | C40: HOSE | D40: 4364945131 | E40: 5571877885 | F40: 7749076520 | G40: 4065343959 | H40: 4204050002 | I40: 6394009821 | J40: 5493847925 | K40: 4702086183 | L40: =VLOOKUP(A40,Sheet1!$A$1:$E$2000,5,FALSE) -> 4646531336 | M40: =(H40-D40)/ABS(D40) -> -0.036860745 | N40: =(I40-E40)/ABS(E40) -> 0.14755024 | O40: =(J40-F40)/ABS(F40) -> -0.29103192 | P40: =(K40-G40)/ABS(G40) -> 0.1566269 | Q40: =(L40-H40)/ABS(H40) -> 0.10525121 | R40: =(SUM(J40:L40)-SUM(F40:H40))/ABS(SUM(F40:H40)) -> -0.073415564 | S40: =SUM(I40:L40)/SUM(E40:H40)-1 -> -0.016390338 | T40: =SUM(I40:L40) -> 21236475265
A41: BSI | B41: Chứng khoán BIDV | C41: HOSE | D41: 137148427862 | E41: 114779704952 | F41: 70008539857 | G41: 91152423672 | H41: 81115038976 | I41: 101899940357 | J41: 215588496422 | K41: 95062757764 | L41: =VLOOKUP(A41,Sheet1!$A$1:$E$2000,5,FALSE) -> 88819056890 | M41: =(H41-D41)/ABS(D41) -> -0.4085602 | N41: =(I41-E41)/ABS(E41) -> -0.11221291 | O41: =(J41-F41)/ABS(F41) -> 2.07946 | P41: =(K41-G41)/ABS(G41) -> 0.042898849 | Q41: =(L41-H41)/ABS(H41) -> 0.094976443 | R41: =(SUM(J41:L41)-SUM(F41:H41))/ABS(SUM(F41:H41)) -> 0.64882327 | S41: =SUM(I41:L41)/SUM(E41:H41)-1 -> 0.40417935 | T41: =SUM(I41:L41) -> 501370251433
A42: BSR | B42: Lọc Hóa dầu Bình Sơn | C42: HOSE | D42: 1143819690777 | E42: 781568179382 | F42: -1210167499868 | G42: -84089620987 | H42: 398719235293 | I42: 845664137644 | J42: 907545618973 | K42: 3061683071313 | L42: =VLOOKUP(A42,Sheet1!$A$1:$E$2000,5,FALSE) -> 8264713781616 | M42: =(H42-D42)/ABS(D42) -> -0.65141426 | N42: =(I42-E42)/ABS(E42) -> 0.082009427 | O42: =(J42-F42)/ABS(F42) -> 1.7499339 | P42: =(K42-G42)/ABS(G42) -> 37.409762 | Q42: =(L42-H42)/ABS(H42) -> 19.728154 | R42: =(SUM(J42:L42)-SUM(F42:H42))/ABS(SUM(F42:H42)) -> 14.660999 | S42: =SUM(I42:L42)/SUM(E42:H42)-1 -> -115.76389 | T42: =SUM(I42:L42) -> 13079606609546
... A111: DXV | B111: Vật liệu Xây dựng Đà Nẵng | C111: HOSE | D111: -660364239 | E111: -1526677032 | F111: -1585578523 | G111: -1888731317 | H111: 33100236 | I111: 425079747 | J111: 218938382 | K111: 137097207 | L111: =VLOOKUP(A111,Sheet1!$A$1:$E$2000,5,FALSE) -> 148132891 | M111: =(H111-D111)/ABS(D111) -> 1.0501242 | N111: =(I111-E111)/ABS(E111) -> 1.2784346 | O111: =(J111-F111)/ABS(F111) -> 1.1380811 | P111: =(K111-G111)/ABS(G111) -> 1.0725869 | Q111: =(L111-H111)/ABS(H111) -> 3.475282 | R111: =(SUM(J111:L111)-SUM(F111:H111))/ABS(SUM(F111:H111)) -> 1.1465091 | S111: =SUM(I111:L111)/SUM(E111:H111)-1 -> -1.187051 | T111: =SUM(I111:L111) -> 929248227
A112: E1VFVN30 | B112: Quỹ ETF DCVFMVN30 | C112: HOSE | L112: =VLOOKUP(A112,Sheet1!$A$1:$E$2000,5,FALSE) -> 0 | M112: =(H112-D112)/ABS(D112) -> #DIV/0! | N112: =(I112-E112)/ABS(E112) -> #DIV/0! | O112: =(J112-F112)/ABS(F112) -> #DIV/0! | P112: =(K112-G112)/ABS(G112) -> #DIV/0! | Q112: =(L112-H112)/ABS(H112) -> #DIV/0! | R112: =(SUM(J112:L112)-SUM(F112:H112))/ABS(SUM(F112:H112)) -> #DIV/0! | S112: =SUM(I112:L112)/SUM(E112:H112)-1 -> #DIV/0! | T112: =SUM(I112:L112) -> 0
A113: EIB | B113: Eximbank | C113: HOSE | D113: 527251000000 | E113: 642838000000 | F113: 721211000000 | G113: 1435504000000 | H113: 658489000000 | I113: 506244000000 | J113: 444688000000 | K113: -472482000000 | L113: =VLOOKUP(A113,Sheet1!$A$1:$E$2000,5,FALSE) -> 269160000000 | M113: =(H113-D113)/ABS(D113) -> 0.24890991 | N113: =(I113-E113)/ABS(E113) -> -0.21248588 | O113: =(J113-F113)/ABS(F113) -> -0.38341484 | P113: =(K113-G113)/ABS(G113) -> -1.3291401 | Q113: =(L113-H113)/ABS(H113) -> -0.59124602 | R113: =(SUM(J113:L113)-SUM(F113:H113))/ABS(SUM(F113:H113)) -> -0.91426341 | S113: =SUM(I113:L113)/SUM(E113:H113)-1 -> -0.7838054 | T113: =SUM(I113:L113) -> 747610000000
A114: ELC | B114: ELCOM | C114: HOSE | D114: 7233556497 | E114: 4185825253 | F114: 9115863591 | G114: 74912430519 | H114: 4775083433 | I114: 14692059584 | J114: 39005431111 | K114: 69174357247 | L114: =VLOOKUP(A114,Sheet1!$A$1:$E$2000,5,FALSE) -> 2653995651 | M114: =(H114-D114)/ABS(D114) -> -0.33987058 | N114: =(I114-E114)/ABS(E114) -> 2.5099553 | O114: =(J114-F114)/ABS(F114) -> 3.278852 | P114: =(K114-G114)/ABS(G114) -> -0.076597078 | Q114: =(L114-H114)/ABS(H114) -> -0.4441991 | R114: =(SUM(J114:L114)-SUM(F114:H114))/ABS(SUM(F114:H114)) -> 0.24808073 | S114: =SUM(I114:L114)/SUM(E114:H114)-1 -> 0.34989698 | T114: =SUM(I114:L114) -> 125525843593
A115: EVE | B115: Everpia | C115: HOSE | D115: 1114824859 | E115: -9378073463 | F115: -29484980365 | G115: 7562164052 | H115: 720558457 | I115: 11626833405 | J115: 18303353419 | K115: 8565390560 | L115: =VLOOKUP(A115,Sheet1!$A$1:$E$2000,5,FALSE) -> 770203562 | M115: =(H115-D115)/ABS(D115) -> -0.35365771 | N115: =(I115-E115)/ABS(E115) -> 2.2397891 | O115: =(J115-F115)/ABS(F115) -> 1.6207687 | P115: =(K115-G115)/ABS(G115) -> 0.13266394 | Q115: =(L115-H115)/ABS(H115) -> 0.068898095 | R115: =(SUM(J115:L115)-SUM(F115:H115))/ABS(SUM(F115:H115)) -> 2.3035851 | S115: =SUM(I115:L115)/SUM(E115:H115)-1 -> -2.2840208 | T115: =SUM(I115:L115) -> 39265780946
A116: EVF | B116: Tài chính Tổng hợp Điện lực | C116: HOSE | D116: 131126000000 | E116: 117887000000 | F116: 180800000000 | G116: 131008000000 | H116: 240480000000 | I116: 241944000000 | J116: 253789000000 | K116: 158124000000 | L116: =VLOOKUP(A116,Sheet1!$A$1:$E$2000,5,FALSE) -> 266631000000 | M116: =(H116-D116)/ABS(D116) -> 0.83396123 | N116: =(I116-E116)/ABS(E116) -> 1.0523383 | O116: =(J116-F116)/ABS(F116) -> 0.40370022 | P116: =(K116-G116)/ABS(G116) -> 0.20697973 | Q116: =(L116-H116)/ABS(H116) -> 0.10874501 | R116: =(SUM(J116:L116)-SUM(F116:H116))/ABS(SUM(F116:H116)) -> 0.22860537 | S116: =SUM(I116:L116)/SUM(E116:H116)-1 -> 0.37350394 | T116: =SUM(I116:L116) -> 920488000000
A117: EVG | B117: Tập đoàn Everland | C117: HOSE | D117: -3117579661 | E117: 30154266753 | F117: 8211327351 | G117: -3829357620 | H117: 10862534485 | I117: 9854229183 | J117: 15013887962 | K117: 42010050458 | L117: =VLOOKUP(A117,Sheet1!$A$1:$E$2000,5,FALSE) -> 18956399299 | M117: =(H117-D117)/ABS(D117) -> 4.4842845 | N117: =(I117-E117)/ABS(E117) -> -0.67320614 | O117: =(J117-F117)/ABS(F117) -> 0.82843617 | P117: =(K117-G117)/ABS(G117) -> 11.970522 | Q117: =(L117-H117)/ABS(H117) -> 0.74511753 | R117: =(SUM(J117:L117)-SUM(F117:H117))/ABS(SUM(F117:H117)) -> 3.9841134 | S117: =SUM(I117:L117)/SUM(E117:H117)-1 -> 0.89068041 | T117: =SUM(I117:L117) -> 85834566902
A118: FCM | B118: Bê tông Phan Vũ Hà Nam | C118: HOSE | D118: 945007431 | E118: -10352427675 | F118: 4360104649 | G118: 6586842182 | H118: 4403581361 | I118: 4359293246 | J118: 3603589240 | K118: 6404312226 | L118: =VLOOKUP(A118,Sheet1!$A$1:$E$2000,5,FALSE) -> 4275275637 | M118: =(H118-D118)/ABS(D118) -> 3.6598378 | N118: =(I118-E118)/ABS(E118) -> 1.421089 | O118: =(J118-F118)/ABS(F118) -> -0.17350854 | P118: =(K118-G118)/ABS(G118) -> -0.027711299 | Q118: =(L118-H118)/ABS(H118) -> -0.029136676 | R118: =(SUM(J118:L118)-SUM(F118:H118))/ABS(SUM(F118:H118)) -> -0.06953188 | S118: =SUM(I118:L118)/SUM(E118:H118)-1 -> 2.7299111 | T118: =SUM(I118:L118) -> 18642470349
A119: FCN | B119: FECON CORP | C119: HOSE | D119: -7327261497 | E119: 11579911025 | F119: 7147180693 | G119: -2130821338 | H119: -6567397288 | I119: 21680880146 | J119: 14617349417 | K119: 2613208704 | L119: =VLOOKUP(A119,Sheet1!$A$1:$E$2000,5,FALSE) -> 31326328494 | M119: =(H119-D119)/ABS(D119) -> 0.10370371 | N119: =(I119-E119)/ABS(E119) -> 0.87228383 | O119: =(J119-F119)/ABS(F119) -> 1.045191 | P119: =(K119-G119)/ABS(G119) -> 2.2263856 | Q119: =(L119-H119)/ABS(H119) -> 5.7699762 | R119: =(SUM(J119:L119)-SUM(F119:H119))/ABS(SUM(F119:H119)) -> 32.30606 | S119: =SUM(I119:L119)/SUM(E119:H119)-1 -> 6.0035552 | T119: =SUM(I119:L119) -> 70237766761
...

Sheet Sheet1
A1: AAA | B1: An Phát Bioplastics | C1: HOSE | E1: 153668061513
A2: AAM | B2: Thủy sản Mekong | C2: HOSE | E2: 2387603772
A3: AAT | B3: Tập đoàn Tiên Sơn Thanh Hóa | C3: HOSE | E3: 490938501
A4: ABR | B4: Đầu tư Nhãn Hiệu Việt | C4: HOSE | E4: 2370604829
A5: ABS | B5: DV Nông nghiệp Bình Thuận | C5: HOSE | E5: -1741076711
A6: ABT | B6: Thủy sản Bến Tre | C6: HOSE | E6: 22273623047
A7: ACB | B7: ACB | C7: HOSE | E7: 4320388000000
A8: ACC | B8: Đầu tư và XD Bình Dương ACC | C8: HOSE | E8: 5708706572
A9: ACG | B9: Gỗ An Cường | C9: HOSE | E9: 111902787167
A10: ACL | B10: Thủy sản CL An Giang | C10: HOSE | E10: 3439078053
A11: ADG | B11: Clever Group | C11: HOSE
A12: ADP | B12: Sơn Á Đông | C12: HOSE | E12: 15837757005
A13: ADS | B13: Dệt sợi DAMSAN | C13: HOSE | E13: 13692968898
A14: AFX | B14: XNK Nông sản Thực phẩm An Giang | C14: HOSE | E14: 18038047215
A15: AGG | B15: Bất động sản An Gia | C15: HOSE | E15: 5015102306
A16: AGR | B16: Agriseco | C16: HOSE | E16: 43488851532
A17: ANT | B17: Rau quả thực phẩm An Giang | C17: HOSE
A18: ANV | B18: Thủy sản Nam Việt | C18: HOSE | E18: 195357833650
A19: APG | B19: Chứng khoán APG | C19: HOSE | E19: 6491373937
A20: APH | B20: Tập đoàn An Phát Holdings | C20: HOSE | E20: 64953188489
A21: ASG | B21: Tập đoàn ASG | C21: HOSE | E21: 49192870182
A22: ASM | B22: Tập đoàn Sao Mai | C22: HOSE | E22: 84641615013
A23: ASP | B23: Dầu khí An Pha | C23: HOSE | E23: 45797129582
A24: AST | B24: Dịch vụ Hàng không Taseco | C24: HOSE | E24: 100919143835
A25: ATP | B25: T.Mại và DV An Thành | C25: HOSE
A26: BAF | B26: Nông nghiệp BAF Việt Nam | C26: HOSE | E26: 206000611406
A27: BCE | B27: XD và GT Bình Dương | C27: HOSE | E27: -21356676077
A28: BCG | B28: Bamboo Capital | C28: HOSE
A29: BCM | B29: Becamex Group | C29: HOSE | E29: 279562828161
A30: BFC | B30: Phân bón Bình Điền | C30: HOSE | E30: 124201533146
A31: BHN | B31: HABECO | C31: HOSE | E31: 77222524813
A32: BIC | B32: Bảo hiểm BIDV | C32: HOSE | E32: 87245176382
A33: BID | B33: BIDV | C33: HOSE | E33: 6800834000000
A34: BKG | B34: Đầu tư BKG Việt Nam | C34: HOSE | E34: 1648718602
A35: BMC | B35: Khoáng sản Bình Định | C35: HOSE | E35: 1481978528
A36: BMI | B36: Bảo hiểm Bảo Minh | C36: HOSE | E36: 55556275286
A37: BMP | B37: Nhựa Bình Minh | C37: HOSE | E37: 303956059754
A38: BRC | B38: Cao su Bến Thành | C38: HOSE | E38: 4646531336
A39: BSI | B39: Chứng khoán BIDV | C39: HOSE | E39: 88819056890
A40: BSR | B40: Lọc Hóa dầu Bình Sơn | C40: HOSE | E40: 8264713781616
...

Sheet LNG
A1: Mã CK | B1: Tên | C1: Sàn | D1: =LNST!H2 -> Q1.25 | E1: =LNST!I2 -> Q2.25 | F1: =LNST!J2 -> Q3.25 | G1: =LNST!K2 -> Q4.25 | H1: =LNST!L2 -> Q1.26
A2: AAA | B2: An Phát Bioplastics | C2: HOSE | D2: 463714514499 | E2: 354139506457 | F2: 347608363938 | G2: 327371053455 | H2: =VLOOKUP(A2,Sheet3!$A$1:$E$2000,5,FALSE) -> 359810543946
A3: AAM | B3: Thủy sản Mekong | C3: HOSE | D3: 7430110397 | E3: 8667864796 | F3: 4539269076 | G3: 552257145 | H3: =VLOOKUP(A3,Sheet3!$A$1:$E$2000,5,FALSE) -> 4831508362
A4: AAT | B4: Tập đoàn Tiên Sơn Thanh Hóa | C4: HOSE | D4: 30943441987 | E4: 19022104206 | F4: 14179904885 | G4: 20284354109 | H4: =VLOOKUP(A4,Sheet3!$A$1:$E$2000,5,FALSE) -> 22352686707
A5: ABR | B5: Đầu tư Nhãn Hiệu Việt | C5: HOSE | D5: 5960116877 | E5: 5773601254 | F5: 5643291226 | G5: 6536782944 | H5: =VLOOKUP(A5,Sheet3!$A$1:$E$2000,5,FALSE) -> 6228645959
A6: ABS | B6: DV Nông nghiệp Bình Thuận | C6: HOSE | D6: 1597477127 | E6: 1491551915 | F6: 1870760535 | G6: 1018512394 | H6: =VLOOKUP(A6,Sheet3!$A$1:$E$2000,5,FALSE) -> 1988618406
A7: ABT | B7: Thủy sản Bến Tre | C7: HOSE | D7: 35216800659 | E7: 54612643215 | F7: 56662332031 | G7: 43740342118 | H7: =VLOOKUP(A7,Sheet3!$A$1:$E$2000,5,FALSE) -> 36323708991
A8: ACB | B8: ACB | C8: HOSE | H8: =VLOOKUP(A8,Sheet3!$A$1:$E$2000,5,FALSE) -> 0
A9: ACC | B9: Đầu tư và XD Bình Dương ACC | C9: HOSE | D9: 22481023583 | E9: 22950738873 | F9: 42206288366 | G9: 24349520283 | H9: =VLOOKUP(A9,Sheet3!$A$1:$E$2000,5,FALSE) -> 15838648017
A10: ACG | B10: Gỗ An Cường | C10: HOSE | D10: 235733214602 | E10: 289721724733 | F10: 335318636284 | G10: 484538374455 | H10: =VLOOKUP(A10,Sheet3!$A$1:$E$2000,5,FALSE) -> 308669637516
A11: ACL | B11: Thủy sản CL An Giang | C11: HOSE | D11: 52023624078 | E11: 61229341614 | F11: 69824671139 | G11: 82877744873 | H11: =VLOOKUP(A11,Sheet3!$A$1:$E$2000,5,FALSE) -> 58398982954
A12: ADG | B12: Clever Group | C12: HOSE | D12: 10511242401 | E12: 17083863089 | F12: 14173186604 | G12: 41647583458 | H12: =VLOOKUP(A12,Sheet3!$A$1:$E$2000,5,FALSE) -> 0
A13: ADP | B13: Sơn Á Đông | C13: HOSE | D13: 38815032242 | E13: 34192375843 | F13: 25524742515 | G13: 30190787885 | H13: =VLOOKUP(A13,Sheet3!$A$1:$E$2000,5,FALSE) -> 29470224206
A14: ADS | B14: Dệt sợi DAMSAN | C14: HOSE | D14: 32025212597 | E14: 71371033231 | F14: 46231695839 | G14: 103365910038 | H14: =VLOOKUP(A14,Sheet3!$A$1:$E$2000,5,FALSE) -> 34596475482
A15: AFX | B15: XNK Nông sản Thực phẩm An Giang | C15: HOSE | D15: 7333729419 | E15: 21025339643 | F15: 12922118164 | G15: 20903238672 | H15: =VLOOKUP(A15,Sheet3!$A$1:$E$2000,5,FALSE) -> 29648193663
A16: AGG | B16: Bất động sản An Gia | C16: HOSE | D16: 75449818771 | E16: 165377214686 | F16: 194400269258 | G16: 148114152614 | H16: =VLOOKUP(A16,Sheet3!$A$1:$E$2000,5,FALSE) -> 36987903787
A17: AGR | B17: Agriseco | C17: HOSE | D17: 66112333288 | E17: 36405211985 | F17: 122456875395 | G17: 95209953556 | H17: =VLOOKUP(A17,Sheet3!$A$1:$E$2000,5,FALSE) -> 110266725334
A18: ANT | B18: Rau quả thực phẩm An Giang | C18: HOSE | D18: 126510816367 | E18: 131129598055 | F18: 121034962600 | G18: 71150410384 | H18: =VLOOKUP(A18,Sheet3!$A$1:$E$2000,5,FALSE) -> 0
A19: ANV | B19: Thủy sản Nam Việt | C19: HOSE | D19: 223695010477 | E19: 486365584101 | F19: 487487993857 | G19: 425383718926 | H19: =VLOOKUP(A19,Sheet3!$A$1:$E$2000,5,FALSE) -> 326307508748
A20: APG | B20: Chứng khoán APG | C20: HOSE | D20: 21331125606 | E20: 31903492057 | F20: 72682990145 | G20: 65548419932 | H20: =VLOOKUP(A20,Sheet3!$A$1:$E$2000,5,FALSE) -> 62308770045
... A25: AST | B25: Dịch vụ Hàng không Taseco | C25: HOSE | D25: 242538767927 | E25: 251107984521 | F25: 294214353928 | G25: 308251562281 | H25: =VLOOKUP(A25,Sheet3!$A$1:$E$2000,5,FALSE) -> 364766626709
A26: ATP | B26: T.Mại và DV An Thành | C26: HOSE | H26: =VLOOKUP(A26,Sheet3!$A$1:$E$2000,5,FALSE) -> 0
A27: BAF | B27: Nông nghiệp BAF Việt Nam | C27: HOSE | D27: 290477202814 | E27: 316368245456 | F27: 263908863897 | G27: -188902792286 | H27: =VLOOKUP(A27,Sheet3!$A$1:$E$2000,5,FALSE) -> 451223734791
A28: BCE | B28: XD và GT Bình Dương | C28: HOSE | D28: -230924048 | E28: 14643360031 | F28: 9685531192 | G28: 141600369390 | H28: =VLOOKUP(A28,Sheet3!$A$1:$E$2000,5,FALSE) -> 5125038280
A29: BCG | B29: Bamboo Capital | C29: HOSE | H29: =VLOOKUP(A29,Sheet3!$A$1:$E$2000,5,FALSE) -> 0
A30: BCM | B30: Becamex Group | C30: HOSE | D30: 704150566074 | E30: 1908031502052 | F30: 509907089589 | G30: 1040043428725 | H30: =VLOOKUP(A30,Sheet3!$A$1:$E$2000,5,FALSE) -> 682650522716
A31: BFC | B31: Phân bón Bình Điền | C31: HOSE | D31: 373987535757 | E31: 413479308160 | F31: 220833922394 | G31: 316994742074 | H31: =VLOOKUP(A31,Sheet3!$A$1:$E$2000,5,FALSE) -> 436762921200
A32: BHN | B32: HABECO | C32: HOSE | D32: 354128221979 | E32: 694602778986 | F32: 738892875385 | G32: 631588480745 | H32: =VLOOKUP(A32,Sheet3!$A$1:$E$2000,5,FALSE) -> 499713563284
A33: BIC | B33: Bảo hiểm BIDV | C33: HOSE | D33: 275085830173 | E33: 249484286207 | F33: 278282724089 | G33: 191366129077 | H33: =VLOOKUP(A33,Sheet3!$A$1:$E$2000,5,FALSE) -> 215854269603
A34: BID | B34: BIDV | C34: HOSE | H34: =VLOOKUP(A34,Sheet3!$A$1:$E$2000,5,FALSE) -> 0
A35: BKG | B35: Đầu tư BKG Việt Nam | C35: HOSE | D35: 6363082290 | E35: 8141536104 | F35: 4581713812 | G35: 7123351141 | H35: =VLOOKUP(A35,Sheet3!$A$1:$E$2000,5,FALSE) -> 4402585364
A36: BMC | B36: Khoáng sản Bình Định | C36: HOSE | D36: 3518948114 | E36: 7621815828 | F36: 9224893700 | G36: 6395516396 | H36: =VLOOKUP(A36,Sheet3!$A$1:$E$2000,5,FALSE) -> 4808904818
A37: BMI | B37: Bảo hiểm Bảo Minh | C37: HOSE | D37: 106939229202 | E37: 101431054124 | F37: 91087580024 | G37: 15402806770 | H37: =VLOOKUP(A37,Sheet3!$A$1:$E$2000,5,FALSE) -> 77627559729
A38: BMP | B38: Nhựa Bình Minh | C38: HOSE | D38: 590170242795 | E38: 610817358498 | F38: 734167408150 | G38: 604409167984 | H38: =VLOOKUP(A38,Sheet3!$A$1:$E$2000,5,FALSE) -> 688068276858
A39: BRC | B39: Cao su Bến Thành | C39: HOSE | D39: 15691705746 | E39: 18479938745 | F39: 16854994260 | G39: 17581085655 | H39: =VLOOKUP(A39,Sheet3!$A$1:$E$2000,5,FALSE) -> 17264707509
A40: BSI | B40: Chứng khoán BIDV | C40: HOSE | D40: 197799476351 | E40: 262408393883 | F40: 423157240034 | G40: 316795712858 | H40: =VLOOKUP(A40,Sheet3!$A$1:$E$2000,5,FALSE) -> 351495830024
A41: BSR | B41: Lọc Hóa dầu Bình Sơn | C41: HOSE | D41: 382335094634 | E41: 1016359178961 | F41: 1008526847756 | G41: 3706697454545 | H41: =VLOOKUP(A41,Sheet3!$A$1:$E$2000,5,FALSE) -> 9506578752065
A42: BTP | B42: Nhiệt điện Bà Rịa | C42: HOSE | D42: 15174606700 | E42: 16368714178 | F42: 9997431193 | G42: 5575551066 | H42: =VLOOKUP(A42,Sheet3!$A$1:$E$2000,5,FALSE) -> 16259959066
A43: BTT | B43: TM - DV Bến Thành | C43: HOSE | D43: 35123275751 | E43: 33028998924 | F43: 34214521004 | G43: 37464422419 | H43: =VLOOKUP(A43,Sheet3!$A$1:$E$2000,5,FALSE) -> 37471388802
A44: BVH | B44: Tập đoàn Bảo Việt | C44: HOSE | D44: 577222965394 | E44: 592598316073 | F44: 244838162662 | G44: -176713115188 | H44: =VLOOKUP(A44,Sheet3!$A$1:$E$2000,5,FALSE) -> 307855270823
...

Sheet Sheet3
A1: AAA | B1: An Phát Bioplastics | C1: HOSE | E1: 359810543946
A2: AAM | B2: Thủy sản Mekong | C2: HOSE | E2: 4831508362
A3: AAT | B3: Tập đoàn Tiên Sơn Thanh Hóa | C3: HOSE | E3: 22352686707
A4: ABR | B4: Đầu tư Nhãn Hiệu Việt | C4: HOSE | E4: 6228645959
A5: ABS | B5: DV Nông nghiệp Bình Thuận | C5: HOSE | E5: 1988618406
A6: ABT | B6: Thủy sản Bến Tre | C6: HOSE | E6: 36323708991
A7: ACB | B7: ACB | C7: HOSE
A8: ACC | B8: Đầu tư và XD Bình Dương ACC | C8: HOSE | E8: 15838648017
A9: ACG | B9: Gỗ An Cường | C9: HOSE | E9: 308669637516
A10: ACL | B10: Thủy sản CL An Giang | C10: HOSE | E10: 58398982954
A11: ADG | B11: Clever Group | C11: HOSE
A12: ADP | B12: Sơn Á Đông | C12: HOSE | E12: 29470224206
A13: ADS | B13: Dệt sợi DAMSAN | C13: HOSE | E13: 34596475482
A14: AFX | B14: XNK Nông sản Thực phẩm An Giang | C14: HOSE | E14: 29648193663
A15: AGG | B15: Bất động sản An Gia | C15: HOSE | E15: 36987903787
A16: AGR | B16: Agriseco | C16: HOSE | E16: 110266725334
A17: ANT | B17: Rau quả thực phẩm An Giang | C17: HOSE
A18: ANV | B18: Thủy sản Nam Việt | C18: HOSE | E18: 326307508748
A19: APG | B19: Chứng khoán APG | C19: HOSE | E19: 62308770045
A20: APH | B20: Tập đoàn An Phát Holdings | C20: HOSE | E20: 360220134446
A21: ASG | B21: Tập đoàn ASG | C21: HOSE | E21: 128360404671
A22: ASM | B22: Tập đoàn Sao Mai | C22: HOSE | E22: 374725884794
A23: ASP | B23: Dầu khí An Pha | C23: HOSE | E23: 118327227424
A24: AST | B24: Dịch vụ Hàng không Taseco | C24: HOSE | E24: 364766626709
A25: ATP | B25: T.Mại và DV An Thành | C25: HOSE
A26: BAF | B26: Nông nghiệp BAF Việt Nam | C26: HOSE | E26: 451223734791
A27: BCE | B27: XD và GT Bình Dương | C27: HOSE | E27: 5125038280
A28: BCG | B28: Bamboo Capital | C28: HOSE
A29: BCM | B29: Becamex Group | C29: HOSE | E29: 682650522716
A30: BFC | B30: Phân bón Bình Điền | C30: HOSE | E30: 436762921200
A31: BHN | B31: HABECO | C31: HOSE | E31: 499713563284
A32: BIC | B32: Bảo hiểm BIDV | C32: HOSE | E32: 215854269603
A33: BID | B33: BIDV | C33: HOSE
A34: BKG | B34: Đầu tư BKG Việt Nam | C34: HOSE | E34: 4402585364
A35: BMC | B35: Khoáng sản Bình Định | C35: HOSE | E35: 4808904818
A36: BMI | B36: Bảo hiểm Bảo Minh | C36: HOSE | E36: 77627559729
A37: BMP | B37: Nhựa Bình Minh | C37: HOSE | E37: 688068276858
A38: BRC | B38: Cao su Bến Thành | C38: HOSE | E38: 17264707509
